2019-11-21 15:49:08,746 ERROR: Exception on /user/Susan [GET] [in c:\dev\vscworkspaces\pythonplay-microblog\venv\lib\site-packages\flask\app.py:1890]
Traceback (most recent call last):
  File "c:\dev\vscworkspaces\pythonplay-microblog\venv\lib\site-packages\sqlalchemy\engine\base.py", line 1245, in _execute_context
    self.dialect.do_execute(
  File "c:\dev\vscworkspaces\pythonplay-microblog\venv\lib\site-packages\sqlalchemy\engine\default.py", line 581, in do_execute
    cursor.execute(statement, parameters)
sqlite3.OperationalError: no such table: followers

The above exception was the direct cause of the following exception:

Traceback (most recent call last):
  File "c:\dev\vscworkspaces\pythonplay-microblog\venv\lib\site-packages\flask\app.py", line 2446, in wsgi_app
    response = self.full_dispatch_request()
  File "c:\dev\vscworkspaces\pythonplay-microblog\venv\lib\site-packages\flask\app.py", line 1951, in full_dispatch_request
    rv = self.handle_user_exception(e)
  File "c:\dev\vscworkspaces\pythonplay-microblog\venv\lib\site-packages\flask\app.py", line 1820, in handle_user_exception
    reraise(exc_type, exc_value, tb)
  File "c:\dev\vscworkspaces\pythonplay-microblog\venv\lib\site-packages\flask\_compat.py", line 39, in reraise
    raise value
  File "c:\dev\vscworkspaces\pythonplay-microblog\venv\lib\site-packages\flask\app.py", line 1949, in full_dispatch_request
    rv = self.dispatch_request()
  File "c:\dev\vscworkspaces\pythonplay-microblog\venv\lib\site-packages\flask\app.py", line 1935, in dispatch_request
    return self.view_functions[rule.endpoint](**req.view_args)
  File "c:\dev\vscworkspaces\pythonplay-microblog\venv\lib\site-packages\flask_login\utils.py", line 261, in decorated_view
    return func(*args, **kwargs)
  File "C:\Dev\VSCWorkspaces\PythonPlay-microblog\app\routes.py", line 32, in user
    return render_template('user.html', user=user, posts=posts)
  File "c:\dev\vscworkspaces\pythonplay-microblog\venv\lib\site-packages\flask\templating.py", line 137, in render_template
    return _render(
  File "c:\dev\vscworkspaces\pythonplay-microblog\venv\lib\site-packages\flask\templating.py", line 120, in _render
    rv = template.render(context)
  File "c:\dev\vscworkspaces\pythonplay-microblog\venv\lib\site-packages\jinja2\asyncsupport.py", line 76, in render
    return original_render(self, *args, **kwargs)
  File "c:\dev\vscworkspaces\pythonplay-microblog\venv\lib\site-packages\jinja2\environment.py", line 1008, in render
    return self.environment.handle_exception(exc_info, True)
  File "c:\dev\vscworkspaces\pythonplay-microblog\venv\lib\site-packages\jinja2\environment.py", line 780, in handle_exception
    reraise(exc_type, exc_value, tb)
  File "c:\dev\vscworkspaces\pythonplay-microblog\venv\lib\site-packages\jinja2\_compat.py", line 37, in reraise
    raise value.with_traceback(tb)
  File "C:\Dev\VSCWorkspaces\PythonPlay-microblog\app\templates\user.html", line 1, in <module>
    {% extends 'base.html' %}
  File "c:\dev\vscworkspaces\pythonplay-microblog\venv\lib\site-packages\jinja2\environment.py", line 1005, in render
    return concat(self.root_render_func(self.new_context(vars)))
  File "C:\Dev\VSCWorkspaces\PythonPlay-microblog\app\templates\user.html", line 14, in root
    <p><a href="{{ url_for('edit_profile') }}">Edit your profile</a></p>
  File "C:\Dev\VSCWorkspaces\PythonPlay-microblog\app\templates\base.html", line 54, in root
  File "C:\Dev\VSCWorkspaces\PythonPlay-microblog\app\templates\user.html", line 41, in block_content
  File "c:\dev\vscworkspaces\pythonplay-microblog\venv\lib\site-packages\jinja2\runtime.py", line 262, in call
    return __obj(*args, **kwargs)
  File "c:\dev\vscworkspaces\pythonplay-microblog\venv\lib\site-packages\sqlalchemy\orm\dynamic.py", line 335, in count
    return self._clone(sess).count()
  File "c:\dev\vscworkspaces\pythonplay-microblog\venv\lib\site-packages\sqlalchemy\orm\query.py", line 3630, in count
    return self.from_self(col).scalar()
  File "c:\dev\vscworkspaces\pythonplay-microblog\venv\lib\site-packages\sqlalchemy\orm\query.py", line 3355, in scalar
    ret = self.one()
  File "c:\dev\vscworkspaces\pythonplay-microblog\venv\lib\site-packages\sqlalchemy\orm\query.py", line 3325, in one
    ret = self.one_or_none()
  File "c:\dev\vscworkspaces\pythonplay-microblog\venv\lib\site-packages\sqlalchemy\orm\query.py", line 3294, in one_or_none
    ret = list(self)
  File "c:\dev\vscworkspaces\pythonplay-microblog\venv\lib\site-packages\sqlalchemy\orm\query.py", line 3367, in __iter__
    return self._execute_and_instances(context)
  File "c:\dev\vscworkspaces\pythonplay-microblog\venv\lib\site-packages\sqlalchemy\orm\query.py", line 3392, in _execute_and_instances
    result = conn.execute(querycontext.statement, self._params)
  File "c:\dev\vscworkspaces\pythonplay-microblog\venv\lib\site-packages\sqlalchemy\engine\base.py", line 982, in execute
    return meth(self, multiparams, params)
  File "c:\dev\vscworkspaces\pythonplay-microblog\venv\lib\site-packages\sqlalchemy\sql\elements.py", line 287, in _execute_on_connection
    return connection._execute_clauseelement(self, multiparams, params)
  File "c:\dev\vscworkspaces\pythonplay-microblog\venv\lib\site-packages\sqlalchemy\engine\base.py", line 1095, in _execute_clauseelement
    ret = self._execute_context(
  File "c:\dev\vscworkspaces\pythonplay-microblog\venv\lib\site-packages\sqlalchemy\engine\base.py", line 1249, in _execute_context
    self._handle_dbapi_exception(
  File "c:\dev\vscworkspaces\pythonplay-microblog\venv\lib\site-packages\sqlalchemy\engine\base.py", line 1476, in _handle_dbapi_exception
    util.raise_from_cause(sqlalchemy_exception, exc_info)
  File "c:\dev\vscworkspaces\pythonplay-microblog\venv\lib\site-packages\sqlalchemy\util\compat.py", line 398, in raise_from_cause
    reraise(type(exception), exception, tb=exc_tb, cause=cause)
  File "c:\dev\vscworkspaces\pythonplay-microblog\venv\lib\site-packages\sqlalchemy\util\compat.py", line 152, in reraise
    raise value.with_traceback(tb)
  File "c:\dev\vscworkspaces\pythonplay-microblog\venv\lib\site-packages\sqlalchemy\engine\base.py", line 1245, in _execute_context
    self.dialect.do_execute(
  File "c:\dev\vscworkspaces\pythonplay-microblog\venv\lib\site-packages\sqlalchemy\engine\default.py", line 581, in do_execute
    cursor.execute(statement, parameters)
sqlalchemy.exc.OperationalError: (sqlite3.OperationalError) no such table: followers
[SQL: SELECT count(*) AS count_1 
FROM (SELECT user.id AS user_id, user.username AS user_username, user.email AS user_email, user.password_hash AS user_password_hash, user.about_me AS user_about_me, user.last_seen AS user_last_seen 
FROM user, followers 
WHERE followers.followed_id = ? AND followers.follower_id = user.id) AS anon_1]
[parameters: (1,)]
(Background on this error at: http://sqlalche.me/e/e3q8)
2019-11-21 15:49:44,002 INFO: Microblog startup [in C:\Dev\VSCWorkspaces\PythonPlay-microblog\app\__init__.py:46]
